Workbook

Sheet 01_EXECUTIVE_DASHBOARD
A1: FORMULA STUDENT VEHICLE DYNAMICS - TRACKWIDTH & KINEMATIC SENSITIVITY MASTER V7
A2: Master Kinematic & Dynamic Cascade Evaluation: Baseline (1200mm) vs Dual-Axle Coupled Proposed Redesign (1280mm)
A4: Subsystem / Metric Parameter | B4: Symbol | C4: Unit | D4: Baseline Value (1200mm) | E4: Proposed Value (1280mm) | F4: Delta / Change | G4: Target & FSAE Rule Validation Status
A5: Front Trackwidth | B5: T_f | C5: mm | D5: ='02_INPUT_VARIABLES'!E9 -> 1200 | E5: ='02_INPUT_VARIABLES'!F9 -> 1280 | F5: =E5-D5 -> 80 | G5: =IF(E5>=1200, "PASS: Track Extended (+80mm)", "WARN") -> PASS: Track Extended (+80mm)
A6: Rear Trackwidth | B6: T_r | C6: mm | D6: ='02_INPUT_VARIABLES'!E10 -> 1140 | E6: ='02_INPUT_VARIABLES'!F10 -> 1140 | F6: =E6-D6 -> 0 | G6: =IF(E6>0, "PASS: Constant Rear Track", "WARN") -> PASS: Constant Rear Track
A7: Trackwidth Ratio (Tr / Tf) | B7: Ratio_T | C7: - | D7: ='04_LOAD_TRANSFER_ROLL_GRIP'!E8 -> 0.95 | E7: ='04_LOAD_TRANSFER_ROLL_GRIP'!F8 -> 0.890625 | F7: =E7-D7 -> -0.059375 | G7: =IF(E7>=0.75, "PASS: FSAE Rule V.1.3.2 (>=0.75)", "FAIL: Violates Rule V.1.3.2") -> PASS: FSAE Rule V.1.3.2 (>=0.75)
A8: Total Vehicle CG Height | B8: h | C8: mm | D8: ='02_INPUT_VARIABLES'!E12 -> 300 | E8: ='02_INPUT_VARIABLES'!F12 -> 300 | F8: =E8-D8 -> 0 | G8: =IF(E8>0, "PASS: Measured via Tilt Test", "CHECK") -> PASS: Measured via Tilt Test
A9: Sprung Mass CG Height (EXPLICIT) | B9: h_s | C9: mm | D9: ='04_LOAD_TRANSFER_ROLL_GRIP'!E12 -> 322.46761 | E9: ='04_LOAD_TRANSFER_ROLL_GRIP'!F12 -> 322.46761 | F9: =E9-D9 -> 0 | G9: =IF(E9>E8, "PASS: h_s > h (Physics Preserved)", "WARN") -> PASS: h_s > h (Physics Preserved)
A10: Front Lower Wishbone Length | B10: L_lower_f | C10: mm | D10: ='02_INPUT_VARIABLES'!E17 -> 293.55 | E10: ='02_INPUT_VARIABLES'!F17 -> 380 | F10: =E10-D10 -> 86.45 | G10: =IF(E10>D10, "PASS: Arm Extended (+40mm/side)", "CHECK") -> PASS: Arm Extended (+40mm/side)
A11: Front Upper Wishbone Length (Proportional) | B11: L_upper_f | C11: mm | D11: ='03_KINEMATIC_CASCADE_CALC'!E6 -> 260.43 | E11: ='03_KINEMATIC_CASCADE_CALC'!F6 -> 0 | F11: =E11-D11 -> -260.43 | G11: =IF(E11>D11, "PASS: Matched Upper Arm Length", "WARN") -> WARN
A12: Rear Lower Wishbone Length | B12: L_lower_r | C12: mm | D12: ='02_INPUT_VARIABLES'!E27 -> 230.67 | E12: ='02_INPUT_VARIABLES'!F27 -> 350 | F12: =E12-D12 -> 119.33 | G12: =IF(E12>0, "PASS: Independent Rear Arm Length", "CHECK") -> PASS: Independent Rear Arm Length
A13: Rear Upper Wishbone Length (Proportional) | B13: L_upper_r | C13: mm | D13: ='03_KINEMATIC_CASCADE_CALC'!E14 -> 202.69 | E13: ='03_KINEMATIC_CASCADE_CALC'!F14 -> 0 | F13: =E13-D13 -> -202.69 | G13: =IF(E13>0, "PASS: Matched Rear Upper Arm", "CHECK") -> CHECK
A14: Front Kingpin Inclination Angle (KPI) | B14: theta_KPI_f | C14: deg | D14: ='03_KINEMATIC_CASCADE_CALC'!E7 -> 10.4 | E14: ='03_KINEMATIC_CASCADE_CALC'!F7 -> 10.4 | F14: =E14-D14 -> 0 | G14: =IF(ABS(E14-D14)<0.01, "PASS: KPI Preserved (Constant)", "WARN") -> PASS: KPI Preserved (Constant)
A15: Front Scrub Radius Target | B15: R_scrub_f | C15: mm | D15: ='03_KINEMATIC_CASCADE_CALC'!E8 -> 53.34 | E15: ='03_KINEMATIC_CASCADE_CALC'!F8 -> 53.34 | F15: =E15-D15 -> 0 | G15: =IF(ABS(E15-D15)<0.01, "PASS: Scrub Radius Preserved (18mm)", "WARN") -> PASS: Scrub Radius Preserved (18mm)
A16: Front View Swing Arm Length (FVSA) | B16: L_FVSA_f | C16: mm | D16: ='03_KINEMATIC_CASCADE_CALC'!E9 -> 2601.7996 | E16: ='03_KINEMATIC_CASCADE_CALC'!F9 -> 380 | F16: =E16-D16 -> -2221.7996 | G16: =IF(E16>D16, "PASS: Longer FVSA (Flatter Arc)", "CHECK") -> CHECK
A17: Front Camber Gain Rate in Roll | B17: dgamma_f/dphi | C17: deg/deg | D17: ='03_KINEMATIC_CASCADE_CALC'!E10 -> 0.12009672 | E17: ='03_KINEMATIC_CASCADE_CALC'!F10 -> 0.82228318 | F17: =E17-D17 -> 0.70218646 | G17: =IF(E17<D17, "PASS: Smoother Camber Gain Rate", "CHECK") -> CHECK
A18: Required Front Tie-Rod Length | B18: L_tierod | C18: mm | D18: ='03_KINEMATIC_CASCADE_CALC'!E11 -> 278.8725 | E18: ='03_KINEMATIC_CASCADE_CALC'!F11 -> 361 | F18: =E18-D18 -> 82.1275 | G18: =IF(E18>D18, "PASS: Extended (Zero Bump Steer)", "WARN") -> PASS: Extended (Zero Bump Steer)
A19: Half-Shaft CV-Joint Angle Delta | B19: Delta_theta_CV | C19: deg | D19: ='03_KINEMATIC_CASCADE_CALC'!E17 -> 0 | E19: ='03_KINEMATIC_CASCADE_CALC'!F17 -> 0 | F19: =E19-D19 -> 0 | G19: =IF(E19<='02_INPUT_VARIABLES'!F35, "PASS: CV Angle Safe (< 15 deg)", "FAIL: Binding Risk") -> PASS: CV Angle Safe (< 15 deg)
A20: Front Roll Stiffness | B20: K_phi_f | C20: Nm/deg | D20: ='04_LOAD_TRANSFER_ROLL_GRIP'!E20 -> 393.05516 | E20: ='04_LOAD_TRANSFER_ROLL_GRIP'!F20 -> 441.74771 | F20: =E20-D20 -> 48.692547 | G20: =IF(E20>D20, "PASS: Front Roll Stiffness Increased", "CHECK") -> PASS: Front Roll Stiffness Increased
A21: Total Roll Stiffness | B21: K_phi_total | C21: Nm/deg | D21: ='04_LOAD_TRANSFER_ROLL_GRIP'!E22 -> 602.62034 | E21: ='04_LOAD_TRANSFER_ROLL_GRIP'!F22 -> 648.41953 | F21: =E21-D21 -> 45.799194 | G21: =IF(E21>D21, "PASS: Total Roll Stiffness Increased", "CHECK") -> PASS: Total Roll Stiffness Increased
A22: Total Vehicle Roll Angle at 1.70g | B22: phi_roll | C22: deg | D22: ='04_LOAD_TRANSFER_ROLL_GRIP'!E28 -> 1.4095685 | E22: ='04_LOAD_TRANSFER_ROLL_GRIP'!F28 -> 1.3045489 | F22: =E22-D22 -> -0.10501966 | G22: =IF(E22<D22, "PASS: Body Roll Angle Reduced", "CHECK") -> PASS: Body Roll Angle Reduced
A23: Front Axle Load Transfer | B23: Delta_W_F_total | C23: N | D23: ='04_LOAD_TRANSFER_ROLL_GRIP'!E33 -> 551.49023 | E23: ='04_LOAD_TRANSFER_ROLL_GRIP'!F33 -> 533.29351 | F23: =E23-D23 -> -18.196724 | G23: =IF(E23<D23, "PASS: Front Load Transfer Reduced", "CHECK") -> PASS: Front Load Transfer Reduced
A24: Rear Axle Load Transfer | B24: Delta_W_R_total | C24: N | D24: ='04_LOAD_TRANSFER_ROLL_GRIP'!E38 -> 403.86584 | E24: ='04_LOAD_TRANSFER_ROLL_GRIP'!F38 -> 385.59618 | F24: =E24-D24 -> -18.26966 | G24: =IF(E24<=D24, "PASS: Rear Load Transfer Stable", "CHECK") -> PASS: Rear Load Transfer Stable
A25: Total Vehicle Load Transfer | B25: Delta_W_total | C25: N | D25: ='04_LOAD_TRANSFER_ROLL_GRIP'!E40 -> 955.35607 | E25: ='04_LOAD_TRANSFER_ROLL_GRIP'!F40 -> 918.88968 | F25: =E25-D25 -> -36.466383 | G25: =IF(E25<D25, "PASS: Total Load Transfer Reduced", "CHECK") -> PASS: Total Load Transfer Reduced
A26: Front Inner Wheel Normal Load | B26: F_z_fi | C26: N | D26: ='04_LOAD_TRANSFER_ROLL_GRIP'!E43 -> -1.3944802 | E26: ='04_LOAD_TRANSFER_ROLL_GRIP'!F43 -> -38.207331 | F26: =E26-D26 -> -36.812851 | G26: =IF(E26>0, "PASS: Positive Load (No Wheel Lift)", "FAIL: Lift") -> FAIL: Lift
A27: Front Axle Cornering Grip | B27: Sum_F_yf | C27: N | D27: ='04_LOAD_TRANSFER_ROLL_GRIP'!E52 -> 1549.9568 | E27: ='04_LOAD_TRANSFER_ROLL_GRIP'!F52 -> 1563.6201 | F27: =E27-D27 -> 13.663266 | G27: =IF(E27>D27, "PASS: Front Axle Grip Increased", "CHECK") -> PASS: Front Axle Grip Increased
A28: Total Vehicle Cornering Grip | B28: Sum_F_y | C28: N | D28: ='04_LOAD_TRANSFER_ROLL_GRIP'!E56 -> 3121.7881 | E28: ='04_LOAD_TRANSFER_ROLL_GRIP'!F56 -> 3554.1182 | F28: =E28-D28 -> 432.33011 | G28: =IF(E28>D28, "PASS: Total Vehicle Grip Increased", "CHECK") -> PASS: Total Vehicle Grip Increased
A29: Handling Balance Margin vs Weight Dist | B29: Handling_Margin | C29: % | D29: ='04_LOAD_TRANSFER_ROLL_GRIP'!E60 -> 0.077261452 | E29: ='04_LOAD_TRANSFER_ROLL_GRIP'!F60 -> 0.13036728 | F29: =E29-D29 -> 0.053105828 | G29: =IF(ABS(E29)<0.05, "PASS: Balanced Understeer Margin", "CHECK") -> CHECK
A30: Ackermann Steering Angle Delta | B30: Delta_delta | C30: deg | D30: ='03_KINEMATIC_CASCADE_CALC'!E21 -> 2.8148479 | E30: ='03_KINEMATIC_CASCADE_CALC'!F21 -> 3.0060808 | F30: =E30-D30 -> 0.19123291 | G30: =IF(E30>0, "PASS: Agility Delta Increased", "CHECK") -> PASS: Agility Delta Increased
A31: Steering Kickback Torque on Scrub Radius | B31: M_kickback | C31: Nm | D31: ='03_KINEMATIC_CASCADE_CALC'!E24 -> 82.674697 | E31: ='03_KINEMATIC_CASCADE_CALC'!F24 -> 83.403496 | F31: =E31-D31 -> 0.72879859 | G31: =IF(E31<=D31*1.1, "PASS: Kickback Force Controlled", "WARN") -> PASS: Kickback Force Controlled
A32: Front Lower Wishbone Buckling Safety Factor | B32: SF_lower_f | C32: - | D32: ='05_STRUCTURAL_STRESS_BUCKLING'!E14 -> 163.28042 | E32: ='05_STRUCTURAL_STRESS_BUCKLING'!F14 -> 96.587169 | F32: =E32-D32 -> -66.693249 | G32: =IF(E32>=1.5, "PASS: Euler Buckling Safe (SF >= 1.5)", "FAIL") -> PASS: Euler Buckling Safe (SF >= 1.5)
A33: Rear Lower Wishbone Buckling Safety Factor | B33: SF_lower_r | C33: - | D33: ='05_STRUCTURAL_STRESS_BUCKLING'!E18 -> 260.75324 | E33: ='05_STRUCTURAL_STRESS_BUCKLING'!F18 -> 89.437575 | F33: =E33-D33 -> -171.31567 | G33: =IF(E33>=1.5, "PASS: Rear Arm Buckling Safe", "FAIL") -> PASS: Rear Arm Buckling Safe
A34: Upper Wishbone Tensile Yield Safety Factor | B34: SF_upper | C34: - | D34: ='05_STRUCTURAL_STRESS_BUCKLING'!E22 -> 77.663685 | E34: ='05_STRUCTURAL_STRESS_BUCKLING'!F22 -> 76.985042 | F34: =E34-D34 -> -0.67864283 | G34: =IF(E34>=2, "PASS: Upper Arm Tensile Yield Safe", "FAIL") -> PASS: Upper Arm Tensile Yield Safe
A35: Upright & Stub Axle Bending Safety Factor | B35: SF_upright | C35: - | D35: ='05_STRUCTURAL_STRESS_BUCKLING'!E27 -> 4.7761961 | E35: ='05_STRUCTURAL_STRESS_BUCKLING'!F27 -> 4.8376353 | F35: =E35-D35 -> 0.061439183 | G35: =IF(E35>=2, "PASS: Upright Bending Moment Safe", "FAIL") -> PASS: Upright Bending Moment Safe
A36: Minimum Chassis Torsional Stiffness Target | B36: K_chassis | C36: Nm/deg | D36: ='05_STRUCTURAL_STRESS_BUCKLING'!E6 -> 723.1444 | E36: ='05_STRUCTURAL_STRESS_BUCKLING'!F6 -> 778.10344 | F36: =E36-D36 -> 54.959033 | G36: =IF(E36>0, "PASS: Target Defined for Frame Team", "CHECK") -> PASS: Target Defined for Frame Team

Sheet 02_INPUT_VARIABLES
A1: FORMULA STUDENT VEHICLE DYNAMICS - DUAL-AXLE PARAMETRIC INPUT MASTER
A2: Independent Front & Rear Axle Hardpoint Specifications (RCVD Ch. 16-18, FSAE 2026 Rules)
A3: Category | B3: Variable Description | C3: Symbol | D3: Unit | E3: Baseline Value (1200mm) | F3: Proposed Value (1280mm) | G3: Engineering Reference / Source
A4: Environment | B4: Gravitational Acceleration | C4: g | D4: m/s^2 | E4: 9.81 | F4: 9.81 | G4: Standard Physics (RCVD Ch. 18)
A5: Vehicle Mass | B5: Total Vehicle Mass (inc. Driver) | C5: m_total | D5: kg | E5: 224.3 | F5: 224.3 | G5: Weigh-in Target (RCVD Ch. 18.2)
A6: Vehicle Mass | B6: Front Weight Distribution Fraction | C6: WD_f | D6: % | E6: 0.5 | F6: 0.45 | G6: Target Balance (RCVD Ch. 18.2)
A7: Vehicle Mass | B7: Front Unsprung Mass (Total Axle) | C7: m_uf | D7: kg | E7: 24.4 | F7: 24.4 | G7: Front Axle Assembly (RCVD Ch. 18.2)
A8: Vehicle Mass | B8: Rear Unsprung Mass (Total Axle) | C8: m_ur | D8: kg | E8: 30.1 | F8: 30.1 | G8: Rear Axle Assembly (RCVD Ch. 18.2)
A9: Track Geometry | B9: Front Trackwidth | C9: T_f | D9: mm | E9: 1200 | F9: 1280 | G9: Primary Input (FSAE Rule V.1.3)
A10: Track Geometry | B10: Rear Trackwidth | C10: T_r | D10: mm | E10: 1140 | F10: 1140 | G10: Primary Input (FSAE Rule V.1.3)
A11: Wheelbase Geometry | B11: Vehicle Wheelbase | C11: L | D11: mm | E11: 1560 | F11: 1560 | G11: Primary Input (FSAE Rule V.1.2)
A12: CG Geometry | B12: Total Vehicle CG Height from Ground | C12: h | D12: mm | E12: 300 | F12: 300 | G12: Tilt Table Test (RCVD Ch. 18.2)
A13: CG Geometry | B13: Front Unsprung CG Height | C13: h_uf | D13: mm | E13: 230 | F13: 230 | G13: Front Wheel Center (RCVD Ch. 18.2)
A14: CG Geometry | B14: Rear Unsprung CG Height | C14: h_ur | D14: mm | E14: 230 | F14: 230 | G14: Rear Wheel Center (RCVD Ch. 18.2)
A15: Roll Center | B15: Front Roll Center Height | C15: z_RF | D15: mm | E15: 10 | F15: 10 | G15: Front Kinematic RC (RCVD Ch. 16.3)
... A17: Front Wishbone | B17: Front Lower Wishbone Arm Length | C17: L_lower_f | D17: mm | E17: 293.55 | F17: 380 | G17: Front Suspension Hardpoint (RCVD Ch. 17)
A18: Front Wishbone | B18: Front upper Wishbone Arm Length | C18: L_upper_f | D18: mm | E18: 260.43
A19: Front Wishbone | B19: Front Upper-to-Lower Arm Length Ratio | C19: Ratio_UL_f | D19: - | E19: =E18/E17 -> 0.88717425 | F19: =F18/F17 -> 0 | G19: Front SLA Ratio (Race Car Design)
A20: Front Wishbone | B20: Front Chassis Inboard Lower Pivot Width | C20: W_inboard_lf | D20: mm | E20: 470 | F20: 440 | G20: Front Pedalbox Frame (Rule V.1)
A21: Front Alignment | B21: Front Static Camber Angle | C21: gamma_0f | D21: deg | E21: -2 | F21: -2 | G21: Alignment Setup (Tune to Win Ch. 3)
A22: Front Alignment | B22: Front Kingpin Inclination Angle (KPI) | C22: theta_KPI_f | D22: deg | E22: 10.4 | F22: 10.4 | G22: Front Upright (Race Car Design Ch. 6)
A23: Front Alignment | B23: Front Caster Angle | C23: theta_caster_f | D23: deg | E23: 5 | F23: 3 | G23: Front Upright (Race Car Design Ch. 6)
A24: Front Alignment | B24: Front Kingpin Offset at Wheel Center | C24: d_KPI_f | D24: mm | E24: 83.8 | F24: 35 | G24: Front Upright (Race Car Design Ch. 6)
A25: Front Alignment | B25: Front Wheel Rim Offset | C25: W_offset_f | D25: mm | E25: 44.5 | F25: 15 | G25: keizer wheels R10x1.25
A26: Front Alignment | B26: Front Scrub Radius Target | C26: R_scrub_f | D26: mm | E26: =53.34 -> 53.34 | F26: 53.34 | G26: Front Patch Offset (Race Car Design)
A27: Rear Wishbone | B27: Rear Lower Wishbone Arm Length | C27: L_lower_r | D27: mm | E27: 230.67 | F27: 350 | G27: Rear Hardpoint (RCVD Ch. 17)
A28: Rear Wishbone | B28: Rear Upper Wishbone Arm Length | C28: L_lower_r | D28: mm | E28: 202.69
A29: Rear Wishbone | B29: Rear Upper-to-Lower Arm Length Ratio | C29: Ratio_UL_r | D29: - | E29: =E28/E27 -> 0.87870117 | F29: =F28/F27 -> 0 | G29: Rear SLA Ratio (Race Car Design)
A30: Rear Wishbone | B30: Rear Chassis Inboard Lower Pivot Width | C30: W_inboard_lr | D30: mm | E30: 500 | F30: 480 | G30: Rear Engine Frame (Rule V.1)
A31: Rear Alignment | B31: Rear Static Camber Angle | C31: gamma_0r | D31: deg | E31: 0 | F31: 0 | G31: Alignment Setup (Tune to Win Ch. 3)
A32: Rear Alignment | B32: Rear Static Toe Angle (Inboard+) | C32: Toe_r | D32: deg | E32: 0 | F32: 0 | G32: Rear Traction Setup (RCVD Ch. 11)
A33: Rear Alignment | B33: Rear Wheel Rim Offset | C33: W_offset_r | D33: mm | E33: 25.4 | F33: 25 | G33: keizer wheels R10x2 (width velg 6")
A34: Rear Drivetrain | B34: Rear Half-Shaft Length | C34: L_halfshaft | D34: mm | E34: 320 | F34: 360 | G34: CV Shaft Length (DesignJudges Axles)
A35: Rear Drivetrain | B35: CV-Joint Max Angular Limit | C35: theta_CV_max | D35: deg | E35: 15 | F35: 15 | G35: CV Joint Limit (DesignJudges Axles)
A36: Steering | B36: Reference Corner Radius | C36: R_corner | D36: m | E36: 6 | F36: 6 | G36: Hairpin Radius (FSAE Rules)
A37: Front Elastic | B37: Front Spring Stiffness Rate | C37: K_sf | D37: N/mm | E37: 35 | F37: 35 | G37: Spring Selection (Tune to Win Ch. 4)
A38: Front Elastic | B38: Front Motion Ratio (Wheel / Spring) | C38: IR_f | D38: - | E38: 1.108 | F38: 1.108 | G38: Pushrod Ratio (RCVD Ch. 16)
A39: Front Elastic | B39: Front Anti-Roll Bar Stiffness | C39: K_arbf | D39: Nm/deg | E39: 0 | F39: 0 | G39: Set 0 for No ARB
A40: Rear Elastic | B40: Rear Spring Stiffness Rate | C40: K_sr | D40: N/mm | E40: 35 | F40: 35 | G40: Spring Selection (Tune to Win Ch. 4)
A41: Rear Elastic | B41: Rear Motion Ratio (Wheel / Spring) | C41: IR_r | D41: - | E41: 0.79 | F41: 0.79 | G41: Pushrod Ratio (RCVD Ch. 16)
...

Sheet 03_KINEMATIC_CASCADE_CALC
A1: KINEMATIC CASCADE & GEOMETRY DEPENDENCY CALCULATIONS
A3: Parameter Description | B3: Symbol | C3: Unit | D3: Formula / Derivation | E3: Baseline Value (1200mm) | F3: Proposed Value (1280mm) | G3: Textbook / Engineering Source
A4: SEKSI 1: FRONT AXLE KINEMATICS & STEERING LINKAGE
A5: Front Lower Wishbone Length | B5: L_lower_f | C5: mm | D5: Input from 02_INPUT_VARIABLES | E5: ='02_INPUT_VARIABLES'!E17 -> 293.55 | F5: ='02_INPUT_VARIABLES'!F17 -> 380 | G5: RCVD Ch. 17
A6: Front Upper Wishbone Length (Proportional) | B6: L_upper_f | C6: mm | D6: L_lower_f * Ratio_UL_f | E6: =E5 * '02_INPUT_VARIABLES'!E19 -> 260.43 | F6: =F5 * '02_INPUT_VARIABLES'!F19 -> 0 | G6: Race Car Design Ch. 6
A7: Front Kingpin Inclination Angle (KPI) | B7: theta_KPI_f | C7: deg | D7: Input from 02_INPUT_VARIABLES | E7: ='02_INPUT_VARIABLES'!E22 -> 10.4 | F7: ='02_INPUT_VARIABLES'!F22 -> 10.4 | G7: RCVD Ch. 17.2
A8: Front Scrub Radius Target | B8: R_scrub_f | C8: mm | D8: Input from 02_INPUT_VARIABLES | E8: ='02_INPUT_VARIABLES'!E26 -> 53.34 | F8: ='02_INPUT_VARIABLES'!F26 -> 53.34 | G8: Race Car Design Ch. 6
A9: Front View Swing Arm Length (FVSA) | B9: L_FVSA_f | C9: mm | D9: L_lower_f / (1 - Ratio_UL_f) | E9: =E5 / (1 - '02_INPUT_VARIABLES'!E19) -> 2601.7996 | F9: =F5 / (1 - '02_INPUT_VARIABLES'!F19) -> 380 | G9: RCVD Ch. 17.3
A10: Front Camber Gain Rate in Roll | B10: dgamma_f/dphi | C10: deg/deg | D10: (h_s - z_RF) / L_FVSA_f | E10: =('04_LOAD_TRANSFER_ROLL_GRIP'!E12 - '02_INPUT_VARIABLES'!E15) / E9 -> 0.12009672 | F10: =('04_LOAD_TRANSFER_ROLL_GRIP'!F12 - '02_INPUT_VARIABLES'!F15) / F9 -> 0.82228318 | G10: RCVD Ch. 17.3
A11: Required Front Tie-Rod Length (Zero Bump Steer) | B11: L_tierod | C11: mm | D11: L_lower_f * 0.95 | E11: =E5 * 0.95 -> 278.8725 | F11: =F5 * 0.95 -> 361 | G11: Prepare to Win Ch. 5
A12: SEKSI 2: REAR AXLE KINEMATICS & DRIVETRAIN ALIGNMENT
A13: Rear Lower Wishbone Length | B13: L_lower_r | C13: mm | D13: Input from 02_INPUT_VARIABLES | E13: ='02_INPUT_VARIABLES'!E27 -> 230.67 | F13: ='02_INPUT_VARIABLES'!F27 -> 350 | G13: RCVD Ch. 17
A14: Rear Upper Wishbone Length (Proportional) | B14: L_upper_r | C14: mm | D14: L_lower_r * Ratio_UL_r | E14: =E13 * '02_INPUT_VARIABLES'!E29 -> 202.69 | F14: =F13 * '02_INPUT_VARIABLES'!F29 -> 0 | G14: Race Car Design Ch. 6
A15: Rear View Swing Arm Length (FVSA) | B15: L_FVSA_r | C15: mm | D15: L_lower_r / (1 - Ratio_UL_r) | E15: =E13 / (1 - '02_INPUT_VARIABLES'!E29) -> 1901.6672 | F15: =F13 / (1 - '02_INPUT_VARIABLES'!F29) -> 350 | G15: RCVD Ch. 17.3
A16: Rear Camber Gain Rate in Roll | B16: dgamma_r/dphi | C16: deg/deg | D16: (h_s - z_RR) / L_FVSA_r | E16: =('04_LOAD_TRANSFER_ROLL_GRIP'!E12 - '02_INPUT_VARIABLES'!E16) / E15 -> 0.1511661 | F16: =('04_LOAD_TRANSFER_ROLL_GRIP'!F12 - '02_INPUT_VARIABLES'!F16) / F15 -> 0.82133603 | G16: RCVD Ch. 17.3
A17: Half-Shaft CV-Joint Angle Delta | B17: Delta_theta_CV | C17: deg | D17: ATAN((T_r_prop - T_r_base)/(2 * L_halfshaft)) * 180 / PI() | E17: =0 -> 0 | F17: =ATAN(('02_INPUT_VARIABLES'!F10 - '02_INPUT_VARIABLES'!E10) / (2 * '02_INPUT_VARIABLES'!F34)) * 180 / PI() -> 0 | G17: DesignJudges Axles Guide
A18: SEKSI 3: STEERING GEOMETRY & ACKERMANN
A19: Inner Wheel Steering Angle (Ackermann) | B19: delta_i | C19: deg | D19: ATAN(L / (R_corner*1000 - T_f/2)) * 180 / PI() | E19: =ATAN('02_INPUT_VARIABLES'!E11 / ('02_INPUT_VARIABLES'!E36*1000 - '02_INPUT_VARIABLES'!E9/2)) * 180 / PI() -> 16.113418 | F19: =ATAN('02_INPUT_VARIABLES'!F11 / ('02_INPUT_VARIABLES'!F36*1000 - '02_INPUT_VARIABLES'!F9/2)) * 180 / PI() -> 16.227361 | G19: RCVD Ch. 19.2
A20: Outer Wheel Steering Angle (Ackermann) | B20: delta_o | C20: deg | D20: ATAN(L / (R_corner*1000 + T_f/2)) * 180 / PI() | E20: =ATAN('02_INPUT_VARIABLES'!E11 / ('02_INPUT_VARIABLES'!E36*1000 + '02_INPUT_VARIABLES'!E9/2)) * 180 / PI() -> 13.29857 | F20: =ATAN('02_INPUT_VARIABLES'!F11 / ('02_INPUT_VARIABLES'!F36*1000 + '02_INPUT_VARIABLES'!F9/2)) * 180 / PI() -> 13.22128 | G20: RCVD Ch. 19.2
A21: Ackermann Steering Angle Delta | B21: Delta_delta | C21: deg | D21: delta_i - delta_o | E21: =E19 - E20 -> 2.8148479 | F21: =F19 - F20 -> 3.0060808 | G21: RCVD Ch. 19.2
A22: SEKSI 4: STEERING FORCES & WEIGHT JACKING
A23: Caster Weight Jacking Vertical Delta | B23: Delta_W_jacking | C23: N | D23: K_Rf * r_f * SIN(caster) * SIN(delta_i) | E23: ='04_LOAD_TRANSFER_ROLL_GRIP'!E18 * '02_INPUT_VARIABLES'!E43 * SIN('02_INPUT_VARIABLES'!E23*PI()/180) * SIN(E19*PI()/180) -> 172.97084 | F23: ='04_LOAD_TRANSFER_ROLL_GRIP'!F18 * '02_INPUT_VARIABLES'!F43 * SIN('02_INPUT_VARIABLES'!F23*PI()/180) * SIN(F19*PI()/180) -> 103.93709 | G23: RCVD Ch. 19.4
A24: Steering Kickback Torque on Scrub Radius | B24: M_kickback | C24: Nm | D24: Sum_F_yf * (R_scrub_f / 1000) | E24: ='04_LOAD_TRANSFER_ROLL_GRIP'!E52 * (E8 / 1000) -> 82.674697 | F24: ='04_LOAD_TRANSFER_ROLL_GRIP'!F52 * (F8 / 1000) -> 83.403496 | G24: Race Car Design Ch. 6

Sheet 04_LOAD_TRANSFER_ROLL_GRIP
A1: INDEPENDENT LOAD TRANSFER & TIRE CORNERING GRIP DYNAMICS
A3: Parameter Description | B3: Symbol | C3: Unit | D3: Formula / Derivation | E3: Baseline Value (1200mm) | F3: Proposed Value (1280mm) | G3: Textbook / Engineering Source
A4: SEKSI 1: MASS, WEIGHT DISTRIBUTION & SPRUNG CG DERIVATION
A5: Total Vehicle Static Weight | B5: W_total | C5: N | D5: m_total * g | E5: ='02_INPUT_VARIABLES'!E5 * '02_INPUT_VARIABLES'!E4 -> 2200.383 | F5: ='02_INPUT_VARIABLES'!F5 * '02_INPUT_VARIABLES'!F4 -> 2200.383 | G5: RCVD Ch. 18.2
A6: Front Axle Static Weight | B6: W_f | C6: N | D6: W_total * WD_f | E6: =E5 * '02_INPUT_VARIABLES'!E6 -> 1100.1915 | F6: =F5 * '02_INPUT_VARIABLES'!F6 -> 990.17235 | G6: RCVD Ch. 18.2
A7: Rear Axle Static Weight | B7: W_r | C7: N | D7: W_total * (1 - WD_f) | E7: =E5 * (1 - '02_INPUT_VARIABLES'!E6) -> 1100.1915 | F7: =F5 * (1 - '02_INPUT_VARIABLES'!F6) -> 1210.2106 | G7: RCVD Ch. 18.2
A8: Trackwidth Ratio (Tr / Tf) | B8: Ratio_T | C8: - | D8: T_r / T_f | E8: ='02_INPUT_VARIABLES'!E10 / '02_INPUT_VARIABLES'!E9 -> 0.95 | F8: ='02_INPUT_VARIABLES'!F10 / '02_INPUT_VARIABLES'!F9 -> 0.890625 | G8: FSAE Rule V.1.3.2
A9: Front Static Normal Load per Wheel | B9: W_f_wheel | C9: N | D9: W_f / 2 | E9: =E6 / 2 -> 550.09575 | F9: =F6 / 2 -> 495.08618 | G9: RCVD Ch. 18.2
A10: Rear Static Normal Load per Wheel | B10: W_r_wheel | C10: N | D10: W_r / 2 | E10: =E7 / 2 -> 550.09575 | F10: =F7 / 2 -> 605.10532 | G10: RCVD Ch. 18.2
A11: Total Sprung Mass | B11: m_s | C11: kg | D11: m_total - m_uf - m_ur | E11: ='02_INPUT_VARIABLES'!E5 - '02_INPUT_VARIABLES'!E7 - '02_INPUT_VARIABLES'!E8 -> 169.8 | F11: ='02_INPUT_VARIABLES'!F5 - '02_INPUT_VARIABLES'!F7 - '02_INPUT_VARIABLES'!F8 -> 169.8 | G11: RCVD Ch. 18.2
A12: Sprung Mass CG Height (EXPLICIT DERIVATION) | B12: h_s | C12: mm | D12: ((m_total*h) - (m_uf*h_uf) - (m_ur*h_ur)) / m_s | E12: =('02_INPUT_VARIABLES'!E5*'02_INPUT_VARIABLES'!E12 - '02_INPUT_VARIABLES'!E7*'02_INPUT_VARIABLES'!E13 - '02_INPUT_VARIABLES'!E8*'02_INPUT_VARIABLES'!E14) / E11 -> 322.46761 | F12: =('02_INPUT_VARIABLES'!F5*'02_INPUT_VARIABLES'!F12 - '02_INPUT_VARIABLES'!F7*'02_INPUT_VARIABLES'!F13 - '02_INPUT_VARIABLES'!F8*'02_INPUT_VARIABLES'!F14) / F11 -> 322.46761 | G12: RCVD Ch. 18.2 (Milliken Eq. 18.12)
A13: SEKSI 2: SUSPENSION & ROLL STIFFNESS RATES
A14: Front Wheel Stiffness Rate | B14: K_Wf | C14: N/mm | D14: K_sf * IR_f^2 | E14: ='02_INPUT_VARIABLES'!E37 * ('02_INPUT_VARIABLES'!E38^2) -> 42.96824 | F14: ='02_INPUT_VARIABLES'!F37 * ('02_INPUT_VARIABLES'!F38^2) -> 42.96824 | G14: RCVD Ch. 16.2
A15: Rear Wheel Stiffness Rate | B15: K_Wr | C15: N/mm | D15: K_sr * IR_r^2 | E15: ='02_INPUT_VARIABLES'!E40 * ('02_INPUT_VARIABLES'!E41^2) -> 21.8435 | F15: ='02_INPUT_VARIABLES'!F40 * ('02_INPUT_VARIABLES'!F41^2) -> 21.8435 | G15: RCVD Ch. 16.2
A16: Front Tire Vertical Stiffness Rate | B16: K_tf | C16: N/mm | D16: Input from 02_INPUT_VARIABLES | E16: ='02_INPUT_VARIABLES'!E44 -> 115 | F16: ='02_INPUT_VARIABLES'!F44 -> 110 | G16: FSAE TTC Data
A17: Rear Tire Vertical Stiffness Rate | B17: K_tr | C17: N/mm | D17: Input from 02_INPUT_VARIABLES | E17: ='02_INPUT_VARIABLES'!E49 -> 120 | F17: ='02_INPUT_VARIABLES'!F49 -> 110 | G17: FSAE TTC Data
A18: Front Wheel Ride Rate (Spring + Tire) | B18: K_Rf | C18: N/mm | D18: (K_Wf * K_tf) / (K_Wf + K_tf) | E18: =(E14 * E16) / (E14 + E16) -> 31.28064 | F18: =(F14 * F16) / (F14 + F16) -> 30.898613 | G18: RCVD Ch. 16.2
A19: Rear Wheel Ride Rate (Spring + Tire) | B19: K_Rr | C19: N/mm | D19: (K_Wr * K_tr) / (K_Wr + K_tr) | E19: =(E15 * E17) / (E15 + E17) -> 18.479662 | F19: =(F15 * F17) / (F15 + F17) -> 18.224524 | G19: RCVD Ch. 16.2
A20: Front Axle Roll Stiffness | B20: K_phi_f | C20: Nm/deg | D20: (T_f^2 * K_Rf)/114600 + K_arbf | E20: =('02_INPUT_VARIABLES'!E9^2 * E18)/114600 + '02_INPUT_VARIABLES'!E39 -> 393.05516 | F20: =('02_INPUT_VARIABLES'!F9^2 * F18)/114600 + '02_INPUT_VARIABLES'!F39 -> 441.74771 | G20: RCVD Ch. 16.4
A21: Rear Axle Roll Stiffness | B21: K_phi_r | C21: Nm/deg | D21: (T_r^2 * K_Rr)/114600 + K_arbr | E21: =('02_INPUT_VARIABLES'!E10^2 * E19)/114600 + '02_INPUT_VARIABLES'!E42 -> 209.56518 | F21: =('02_INPUT_VARIABLES'!F10^2 * F19)/114600 + '02_INPUT_VARIABLES'!F42 -> 206.67182 | G21: RCVD Ch. 16.4
A22: Total Suspension Roll Stiffness | B22: K_phi_total | C22: Nm/deg | D22: K_phi_f + K_phi_r | E22: =E20 + E21 -> 602.62034 | F22: =F20 + F21 -> 648.41953 | G22: RCVD Ch. 16.4
A23: SEKSI 3: BODY ROLL DYNAMICS & ROLL MOMENT
A24: Roll Axis Height at CG Position | B24: z_RA | C24: mm | D24: z_RF + (z_RR - z_RF) * (1 - WD_f) | E24: ='02_INPUT_VARIABLES'!E15 + ('02_INPUT_VARIABLES'!E16 - '02_INPUT_VARIABLES'!E15)*(1 - '02_INPUT_VARIABLES'!E6) -> 22.5 | F24: ='02_INPUT_VARIABLES'!F15 + ('02_INPUT_VARIABLES'!F16 - '02_INPUT_VARIABLES'!F15)*(1 - '02_INPUT_VARIABLES'!F6) -> 23.75 | G24: RCVD Ch. 16.3
A25: Sprung Mass Roll Moment Arm (EXPLICIT h_s - z_RA) | B25: h_a | C25: mm | D25: h_s - z_RA | E25: =E12 - E24 -> 299.96761 | F25: =F12 - F24 -> 298.71761 | G25: RCVD Ch. 18.2 (Milliken Eq. 18.14)
A26: Total Vehicle Roll Moment | B26: M_R | C26: Nm | D26: m_s * g * A_y * (h_a / 1000) | E26: =E11 * '02_INPUT_VARIABLES'!E4 * '02_INPUT_VARIABLES'!E58 * (E25 / 1000) -> 849.43466 | F26: =F11 * '02_INPUT_VARIABLES'!F4 * '02_INPUT_VARIABLES'!F58 * (F25 / 1000) -> 845.89496 | G26: RCVD Ch. 18.2
A27: Vehicle Body Roll Gradient | B27: phi_per_Ay | C27: deg/g | D27: M_R / K_phi_total / A_y | E27: =E26 / E22 / '02_INPUT_VARIABLES'!E58 -> 0.82915795 | F27: =F26 / F22 / '02_INPUT_VARIABLES'!F58 -> 0.76738169 | G27: RCVD Ch. 16.4
A28: Total Body Roll Angle at Target A_y | B28: phi_roll | C28: deg | D28: phi_per_Ay * A_y | E28: =E27 * '02_INPUT_VARIABLES'!E58 -> 1.4095685 | F28: =F27 * '02_INPUT_VARIABLES'!F58 -> 1.3045489 | G28: RCVD Ch. 16.4
A29: SEKSI 4: INDEPENDENT LOAD TRANSFER CALCULATIONS
A30: Front Unsprung Load Transfer | B30: Delta_W_uf | C30: N | D30: A_y * m_uf * g * (h_uf / T_f) | E30: ='02_INPUT_VARIABLES'!E58 * '02_INPUT_VARIABLES'!E7 * '02_INPUT_VARIABLES'!E4 * ('02_INPUT_VARIABLES'!E13 / '02_INPUT_VARIABLES'!E9) -> 77.99277 | F30: ='02_INPUT_VARIABLES'!F58 * '02_INPUT_VARIABLES'!F7 * '02_INPUT_VARIABLES'!F4 * ('02_INPUT_VARIABLES'!F13 / '02_INPUT_VARIABLES'!F9) -> 73.118222 | G30: RCVD Ch. 18.2 (Milliken Eq. 18.16)
A31: Front Geometric Link Load Transfer | B31: Delta_W_sff | C31: N | D31: A_y * m_s * g * WD_f * (z_RF / T_f) | E31: ='02_INPUT_VARIABLES'!E58 * E11 * '02_INPUT_VARIABLES'!E4 * '02_INPUT_VARIABLES'!E6 * ('02_INPUT_VARIABLES'!E15 / '02_INPUT_VARIABLES'!E9) -> 11.798977 | F31: ='02_INPUT_VARIABLES'!F58 * F11 * '02_INPUT_VARIABLES'!F4 * '02_INPUT_VARIABLES'!F6 * ('02_INPUT_VARIABLES'!F15 / '02_INPUT_VARIABLES'!F9) -> 9.9553873 | G31: RCVD Ch. 18.2 (Milliken Eq. 18.17)
A32: Front Elastic Roll Load Transfer | B32: Delta_W_scf | C32: N | D32: (K_phi_f / K_phi_total) * M_R / (T_f / 1000) | E32: =(E20 / E22) * E26 / ('02_INPUT_VARIABLES'!E9 / 1000) -> 461.69848 | F32: =(F20 / F22) * F26 / ('02_INPUT_VARIABLES'!F9 / 1000) -> 450.2199 | G32: RCVD Ch. 18.2 (Milliken Eq. 18.18)
A33: TOTAL FRONT AXLE LOAD TRANSFER | B33: Delta_W_F_total | C33: N | D33: Delta_W_uf + Delta_W_sff + Delta_W_scf | E33: =E30 + E31 + E32 -> 551.49023 | F33: =F30 + F31 + F32 -> 533.29351 | G33: RCVD Ch. 18.2
A34: Front Fraction Load Transfer | B34: FLT_f | C34: % | D34: Delta_W_F_total / W_f | E34: =E33 / E6 -> 0.50126749 | F34: =F33 / F6 -> 0.53858655 | G34: RCVD Ch. 18.3
A35: Rear Unsprung Load Transfer | B35: Delta_W_ur | C35: N | D35: A_y * m_ur * g * (h_ur / T_r) | E35: ='02_INPUT_VARIABLES'!E58 * '02_INPUT_VARIABLES'!E8 * '02_INPUT_VARIABLES'!E4 * ('02_INPUT_VARIABLES'!E14 / '02_INPUT_VARIABLES'!E10) -> 101.2762 | F35: ='02_INPUT_VARIABLES'!F58 * '02_INPUT_VARIABLES'!F8 * '02_INPUT_VARIABLES'!F4 * ('02_INPUT_VARIABLES'!F14 / '02_INPUT_VARIABLES'!F10) -> 101.2762 | G35: RCVD Ch. 18.2
A36: Rear Geometric Link Load Transfer | B36: Delta_W_sfr | C36: N | D36: A_y * m_s * g * (1 - WD_f) * (z_RR / T_r) | E36: ='02_INPUT_VARIABLES'!E58 * E11 * '02_INPUT_VARIABLES'!E4 * (1 - '02_INPUT_VARIABLES'!E6) * ('02_INPUT_VARIABLES'!E16 / '02_INPUT_VARIABLES'!E10) -> 43.469917 | F36: ='02_INPUT_VARIABLES'!F58 * F11 * '02_INPUT_VARIABLES'!F4 * (1 - '02_INPUT_VARIABLES'!F6) * ('02_INPUT_VARIABLES'!F16 / '02_INPUT_VARIABLES'!F10) -> 47.816909 | G36: RCVD Ch. 18.2
A37: Rear Elastic Roll Load Transfer | B37: Delta_W_scr | C37: N | D37: (K_phi_r / K_phi_total) * M_R / (T_r / 1000) | E37: =(E21 / E22) * E26 / ('02_INPUT_VARIABLES'!E10 / 1000) -> 259.11972 | F37: =(F21 / F22) * F26 / ('02_INPUT_VARIABLES'!F10 / 1000) -> 236.50307 | G37: RCVD Ch. 18.2
A38: TOTAL REAR AXLE LOAD TRANSFER | B38: Delta_W_R_total | C38: N | D38: Delta_W_ur + Delta_W_sfr + Delta_W_scr | E38: =E35 + E36 + E37 -> 403.86584 | F38: =F35 + F36 + F37 -> 385.59618 | G38: RCVD Ch. 18.2
A39: Rear Fraction Load Transfer | B39: FLT_r | C39: % | D39: Delta_W_R_total / W_r | E39: =E38 / E7 -> 0.36708685 | F39: =F38 / F7 -> 0.31861906 | G39: RCVD Ch. 18.3
A40: TOTAL VEHICLE LOAD TRANSFER | B40: Delta_W_total | C40: N | D40: Delta_W_F_total + Delta_W_R_total | E40: =E33 + E38 -> 955.35607 | F40: =F33 + F38 -> 918.88968 | G40: RCVD Ch. 18.2
A41: SEKSI 5: DYNAMIC NORMAL LOADS & TIRE CORNERING GRIP
...

Sheet 05_STRUCTURAL_STRESS_BUCKLING
A1: WISHBONE EULER BUCKLING, TENSILE YIELD & UPRIGHT BENDING STRESS
A3: Parameter Description | B3: Symbol | C3: Unit | D3: Formula / Derivation | E3: Baseline Value (1200mm) | F3: Proposed Value (1280mm) | G3: Textbook / Engineering Source
A4: SEKSI 1: CHASSIS TORSIONAL STIFFNESS TARGET
A5: Total Suspension Roll Stiffness | B5: K_phi_total | C5: Nm/deg | D5: Input from 04_LOAD_TRANSFER_ROLL_GRIP | E5: ='04_LOAD_TRANSFER_ROLL_GRIP'!E22 -> 602.62034 | F5: ='04_LOAD_TRANSFER_ROLL_GRIP'!F22 -> 648.41953 | G5: RCVD Ch. 16.4
A6: Minimum Required Chassis Torsional Stiffness | B6: K_chassis | C6: Nm/deg | D6: 1.2 * K_phi_total | E6: =1.2 * E5 -> 723.1444 | F6: =1.2 * F5 -> 778.10344 | G6: Race Car Design Ch. 8
A7: Chassis to Suspension Stiffness Ratio | B7: Ratio_K | C7: - | D7: K_chassis / K_phi_total | E7: =E6 / E5 -> 1.2 | F7: =F6 / F5 -> 1.2 | G7: Race Car Design Ch. 8
A8: SEKSI 2: FRONT LOWER WISHBONE EULER BUCKLING ANALYSIS
A9: Tube Inner Diameter (ID) | B9: ID | C9: mm | D9: OD - 2 * t_wall | E9: ='02_INPUT_VARIABLES'!E53 - 2*'02_INPUT_VARIABLES'!E54 -> 22.1 | F9: ='02_INPUT_VARIABLES'!F53 - 2*'02_INPUT_VARIABLES'!F54 -> 22.1 | G9: Mechanics of Materials
A10: Tube Cross-Sectional Area | B10: A_tube | C10: mm^2 | D10: PI() / 4 * (OD^2 - ID^2) | E10: =PI()/4 * ('02_INPUT_VARIABLES'!E53^2 - E9^2) -> 123.11116 | F10: =PI()/4 * ('02_INPUT_VARIABLES'!F53^2 - F9^2) -> 123.11116 | G10: Mechanics of Materials
A11: Tube Area Moment of Inertia | B11: I_tube | C11: mm^4 | D11: PI() / 64 * (OD^4 - ID^4) | E11: =PI()/64 * ('02_INPUT_VARIABLES'!E53^4 - E9^4) -> 8722.195 | F11: =PI()/64 * ('02_INPUT_VARIABLES'!F53^4 - F9^4) -> 8722.195 | G11: Mechanics of Materials
A12: Peak Axial Compression Load on Front Lower Wishbone | B12: P_comp_lower_f | C12: N | D12: (Sum_F_yf / 2) * 1.5 | E12: =('04_LOAD_TRANSFER_ROLL_GRIP'!E52 / 2) * 1.5 -> 1162.4676 | F12: =('04_LOAD_TRANSFER_ROLL_GRIP'!F52 / 2) * 1.5 -> 1172.7151 | G12: Engineer to Win Ch. 5
A13: Critical Euler Buckling Load (Front Lower Arm) | B13: P_crit_lower_f | C13: N | D13: (PI()^2 * E_modulus * I_tube) / L_lower_f^2 | E13: =(PI()^2 * '02_INPUT_VARIABLES'!E55 * E11) / ('02_INPUT_VARIABLES'!E17^2) -> 189808.2 | F13: =(PI()^2 * '02_INPUT_VARIABLES'!F55 * F11) / ('02_INPUT_VARIABLES'!F17^2) -> 113269.23 | G13: Engineer to Win Ch. 5
A14: Front Lower Wishbone Buckling Safety Factor | B14: SF_lower_f | C14: - | D14: P_crit_lower_f / P_comp_lower_f | E14: =E13 / E12 -> 163.28042 | F14: =F13 / F12 -> 96.587169 | G14: FSAE Rule Standard (SF >= 1.5)
A15: SEKSI 3: REAR LOWER WISHBONE EULER BUCKLING ANALYSIS
A16: Peak Axial Compression Load on Rear Lower Wishbone | B16: P_comp_lower_r | C16: N | D16: (Sum_F_yr / 2) * 1.5 | E16: =('04_LOAD_TRANSFER_ROLL_GRIP'!E55 / 2) * 1.5 -> 1178.8735 | F16: =('04_LOAD_TRANSFER_ROLL_GRIP'!F55 / 2) * 1.5 -> 1492.8736 | G16: Engineer to Win Ch. 5
A17: Critical Euler Buckling Load (Rear Lower Arm) | B17: P_crit_lower_r | C17: N | D17: (PI()^2 * E_modulus * I_tube) / L_lower_r^2 | E17: =(PI()^2 * '02_INPUT_VARIABLES'!E55 * E11) / ('02_INPUT_VARIABLES'!E27^2) -> 307395.08 | F17: =(PI()^2 * '02_INPUT_VARIABLES'!F55 * F11) / ('02_INPUT_VARIABLES'!F27^2) -> 133518.99 | G17: Engineer to Win Ch. 5
A18: Rear Lower Wishbone Buckling Safety Factor | B18: SF_lower_r | C18: - | D18: P_crit_lower_r / P_comp_lower_r | E18: =E17 / E16 -> 260.75324 | F18: =F17 / F16 -> 89.437575 | G18: FSAE Rule Standard (SF >= 1.5)
A19: SEKSI 4: UPPER WISHBONE TENSILE YIELD ANALYSIS
A20: Peak Axial Tension Load on Upper Wishbone | B20: P_tensile_upper | C20: N | D20: P_comp_lower_f * 0.45 | E20: =E12 * 0.45 -> 523.11043 | F20: =F12 * 0.45 -> 527.72178 | G20: Race Car Design Ch. 6
A21: Tensile Stress on Upper Wishbone Tube | B21: Sigma_upper | C21: MPa | D21: P_tensile_upper / A_tube | E21: =E20 / E10 -> 4.2490902 | F21: =F20 / F10 -> 4.286547 | G21: Mechanics of Materials
A22: Upper Wishbone Tensile Yield Safety Factor | B22: SF_upper | C22: - | D22: Sigma_y / Sigma_upper | E22: ='02_INPUT_VARIABLES'!E56 / E21 -> 77.663685 | F22: ='02_INPUT_VARIABLES'!F56 / F21 -> 76.985042 | G22: FSAE Rule Standard (SF >= 2.0)
A23: SEKSI 5: UPRIGHT & STUB AXLE BENDING MOMENT
A24: Bending Moment on Upright Stub Axle | B24: M_stub | C24: Nm | D24: (F_y_fo * L_stub + F_z_fo * R_scrub_f) / 1000 | E24: =('04_LOAD_TRANSFER_ROLL_GRIP'!E50 * '02_INPUT_VARIABLES'!E57 + '04_LOAD_TRANSFER_ROLL_GRIP'!E42 * '02_INPUT_VARIABLES'!E26) / 1000 -> 105.98678 | F24: =('04_LOAD_TRANSFER_ROLL_GRIP'!F50 * '02_INPUT_VARIABLES'!F57 + '04_LOAD_TRANSFER_ROLL_GRIP'!F42 * '02_INPUT_VARIABLES'!F26) / 1000 -> 104.64073 | G24: Race Car Design Ch. 6
A25: Section Modulus of Stub Axle (25mm Solid) | B25: Z_stub | C25: mm^3 | D25: (PI() * 25^3) / 32 | E25: =(PI() * 25^3) / 32 -> 1533.9808 | F25: =(PI() * 25^3) / 32 -> 1533.9808 | G25: Mechanics of Materials
A26: Stub Axle Bending Stress | B26: Sigma_stub | C26: MPa | D26: (M_stub * 1000) / Z_stub | E26: =(E24 * 1000) / E25 -> 69.092641 | F26: =(F24 * 1000) / F25 -> 68.215147 | G26: Mechanics of Materials
A27: Upright & Stub Axle Bending Safety Factor | B27: SF_upright | C27: - | D27: Sigma_y / Sigma_stub | E27: ='02_INPUT_VARIABLES'!E56 / E26 -> 4.7761961 | F27: ='02_INPUT_VARIABLES'!F56 / F26 -> 4.8376353 | G27: FSAE Rule Standard (SF >= 2.0)

Sheet 06_SIMULATION_CONFIG
A1: Variable | B1: Value | C1: Unit | D1: Description | F1: FRONT TRACK SCREENING ONLY
A2: front_track_min_mm | B2: 1200 | C2: mm | D2: Minimum front track width sweep | F2: Column F remains unfinished and is not read.
A3: front_track_max_mm | B3: 1280 | C3: mm | D3: Maximum front track width sweep | F3: Historical Excel dashboards are not updated MATLAB study results.
A4: track_step_mm | B4: 5 | C4: mm | D4: Track width sweep increment
A5: rear_track_delta_mode | B5: fixed | C5: text | D5: Front-only study: rear track held at baseline column E.
A6: tire_section_width_mm | B6: 205 | C6: mm | D6: Overall tyre section width used for vehicle envelope
A7: cone_safety_margin_m | B7: 0.2 | C7: m/side | D7: Minimum tyre-to-cone safety margin
A8: max_speed_kph | B8: 105 | C8: km/h | D8: Vehicle top speed limit
A9: max_accel_mps2 | B9: 5 | C9: m/s^2 | D9: Maximum longitudinal acceleration
A10: max_brake_mps2 | B10: 10 | C10: m/s^2 | D10: Maximum braking deceleration magnitude
A11: cornering_safety_factor | B11: 0.95 | C11: - | D11: Fraction of calculated lateral grip used
A12: curvature_smoothing_points | B12: 11 | C12: points | D12: Curvature estimation window
A13: speed_profile_iterations | B13: 100 | C13: passes | D13: Maximum passes; convergence is checked, not assumed.
A14: track_declared_length_m | B14: 1050 | C14: m | D14: User supplied length; not independently verified official geometry.
A15: track_width_m | B15: 5 | C15: m | D15: Nominal cone corridor width
A16: skidpad_inner_diameter_m | B16: 15.25 | C16: m | D16: Inner circle diameter from skidpad diagram
A17: skidpad_lane_width_m | B17: 3 | C17: m | D17: Width between inner and outer cone circles
... A20: skidpad_max_steer_deg | B20: 35 | C20: deg | D20: ASSUMED ideal road-wheel limit; NOT measured fixed-rack capability.
A21: motion_ratio_convention | B21: spring_over_wheel | C21: text | D21: Preserves original Kspring*IR^2. Original input label says wheel/spring: VERIFY MEASURED DEFINITION.
A22: path_scale_mode | B22: raw | C22: text | D22: raw or uniform_to_declared_length. Uniform mode scales coordinates, distance and curvature together.
A23: speed_convergence_mps | B23: 1e-08 | C23: m/s | D23: Maximum change in the periodic speed solution before accepting convergence.
A24: run_sensitivity | B24: 1 | C24: 0/1 | D24: Run baseline-versus-candidate perturbations; assumptions, not confidence intervals.
A25: sensitivity_mu_fraction | B25: 0.1 | C25: fraction | D25: Example proportional perturbation of the full mu(Fz) curve: plus/minus 10%.
A26: sensitivity_h_mm | B26: 20 | C26: mm | D26: Example CG-height perturbation: plus/minus 20 mm; not measured uncertainty.
